Workbook

Sheet IS
A1: Ticker | B1: TGT
A2: Company | B2: Target
A4: (millions, except per share data) | B4: 2011 | C4: 2012 | D4: 2013 | E4: 2014
A6: Sales | B6: 68466 | C6: 71960 | D6: 70626 | E6: 71936
A7: Credit card revenues | B7: 1399 | C7: 1341 | D7: 653 | E7: 682
A8: Total revenues | B8: =SUM(B6:B7) -> 69865 | C8: =SUM(C6:C7) -> 73301 | D8: =SUM(D6:D7) -> 71279 | E8: =SUM(E6:E7) -> 72618
A9: Cost of sales | B9: 47860 | C9: 50568 | D9: 50039 | E9: 51278
A10: Gross Profit | B10: =B8-B9 -> 22005 | C10: =C8-C9 -> 22733 | D10: =D8-D9 -> 21240 | E10: =E8-E9 -> 21340
A11: Selling, general and administrative expenses | B11: 14106 | C11: 14643 | D11: 14465 | E11: 14676
A12: Credit card expenses | B12: 446 | C12: 467 | D12: 0 | E12: 0
A13: EBITDA | B13: =B10-SUM(B11:B12) -> 7453 | C13: =C10-SUM(C11:C12) -> 7623 | D13: =D10-SUM(D11:D12) -> 6775 | E13: =E10-SUM(E11:E12) -> 6664
A14: Depreciation and amortization | B14: 2131 | C14: 2044 | D14: 1996 | E14: 2129
A15: Gain on receivables held for sale | B15: 0 | C15: 0 | D15: 0 | E15: 0
A16: One Time Charges (Gain) | B16: 0 | C16: -161 | D16: -391 | E16: 0
A17: EBIT | B17: =B13-B14+B15-B16 -> 5322 | C17: =C13-C14+C15-C16 -> 5740 | D17: =D13-D14+D15-D16 -> 5170 | E17: =E13-E14+E15-E16 -> 4535
A18: Interest expense | B18: 866 | C18: 684 | D18: 1049 | E18: 882
A19: EBT | B19: =B17-B18 -> 4456 | C19: =C17-C18 -> 5056 | D19: =D17-D18 -> 4121 | E19: =E17-E18 -> 3653
A20: Provision for income taxes | B20: 1527 | C20: 1741 | D20: 1427 | E20: 1204
A21: Net earnings | B21: =B19-B20 -> 2929 | C21: =C19-C20 -> 3315 | D21: =D19-D20 -> 2694 | E21: =E19-E20 -> 2449
A22: Dicontinued Operations, net of tax | C22: -316 | D22: -723 | E22: -4085
A23: Net (loss)/earnings | B23: =SUM(B21:B22) -> 2929 | C23: =SUM(C21:C22) -> 2999 | D23: =SUM(D21:D22) -> 1971 | E23: =SUM(E21:E22) -> -1636
A24: Basic earnings per share | B24: =B23/B26 -> 4.376214 | C24: =C23/C26 -> 4.5213327 | D24: =D23/D26 -> 3.0710502 | E24: =E23/E26 -> -2.5558506
A26: Weighted average common shares outstanding | B26: 669.3 | C26: 663.3 | D26: 641.8 | E26: 640.1

Sheet BS
A1: Ticker | B1: TGT
A2: Company | B2: Target
B4: 2011 | C4: 2012 | D4: 2013 | E4: 2014
A6: Assets
A7: Cash and cash equivalents | B7: 794 | C7: 784 | D7: 695 | E7: 2210
A8: Credit card receivables, held for sale | B8: 0 | C8: 5841 | D8: 0 | E8: 0
A9: Credit card receivable | B9: 5927 | C9: 0 | D9: 0 | E9: 0
A10: Inventory | B10: 7918 | C10: 7903 | D10: 8766 | E10: 8790
A11: Other current assets | B11: 1810 | C11: 1860 | D11: 2112 | E11: 3087
A12: Total current assets | B12: =SUM(B7:B11) -> 16449 | C12: =SUM(C7:C11) -> 16388 | D12: =SUM(D7:D11) -> 11573 | E12: =SUM(E7:E11) -> 14087
A14: Property and equipment
A15: Land | B15: 6122 | C15: 6206 | D15: 6234 | E15: 6127
A16: Buildings and improvements | B16: 26837 | C16: 28653 | D16: 30356 | E16: 26614
A17: Fixtures and equipment | B17: 5141 | C17: 5362 | D17: 8347 | E17: 5346
A18: Computer hardware and software | B18: 2468 | C18: 2567 | D18: 0 | E18: 2553
A19: Construction-in-progress | B19: 963 | C19: 1176 | D19: 843 | E19: 424
A20: Accumulated depreciation | B20: -12382 | C20: -13311 | D20: -14402 | E20: -15106
A21: Property and equipment, net | B21: =SUM(B15:B20) -> 29149 | C21: =SUM(C15:C20) -> 30653 | D21: =SUM(D15:D20) -> 31378 | E21: =SUM(E15:E20) -> 25958
A22: Other noncurrent assets | B22: 1032 | C22: 1122 | D22: 1602 | E22: 1359
A23: Total assets | B23: =B12+B21+B22 -> 46630 | C23: =C12+C21+C22 -> 48163 | D23: =D12+D21+D22 -> 44553 | E23: =E12+E21+E22 -> 41404
A25: Liabilities and shareholders' investment
A26: Accounts payable | B26: 6857 | C26: 7056 | D26: 7683 | E26: 7759
A27: Accrued and other current liabilities | B27: 3644 | C27: 3981 | D27: 3934 | E27: 3783
A28: Unsecured debt and other borrowings | B28: 3036 | C28: 1494 | D28: 1160 | E28: 194
A29: Nonrecourse debt collateralized by credit card receivables | B29: 750 | C29: 1500 | D29: 0
A30: Total current liabilities | B30: =SUM(B26:B29) -> 14287 | C30: =SUM(C26:C29) -> 14031 | D30: =SUM(D26:D29) -> 12777 | E30: =SUM(E26:E29) -> 11736
A31: Unsecured debt and other borrowings | B31: 13447 | C31: 14654 | D31: 12622 | E31: 12705
A32: Nonrecourse debt collateralized by credit card receivables | B32: 250 | C32: 0 | D32: 0 | E32: 0
A33: Deferred income taxes | B33: 1191 | C33: 1311 | D33: 1433 | E33: 1321
A34: Other noncurrent liabilities | B34: 1634 | C34: 1609 | D34: 1490 | E34: 1645
A35: Total noncurrent liabilities | B35: =SUM(B31:B34) -> 16522 | C35: =SUM(C31:C34) -> 17574 | D35: =SUM(D31:D34) -> 15545 | E35: =SUM(E31:E34) -> 15671
A36: Total Liabilities | B36: =B35+B30 -> 30809 | C36: =C35+C30 -> 31605 | D36: =D35+D30 -> 28322 | E36: =E35+E30 -> 27407
A38: Shareholders' investment
A39: Common stock | B39: 56 | C39: 54 | D39: 53 | E39: 53
A40: Additional paid-in capital | B40: 3487 | C40: 3925 | D40: 4470 | E40: 4899
A41: Retained earnings | B41: 12959 | C41: 13155 | D41: 12599 | E41: 9644
A42: Accumulated other comprehensive loss
A43: Pension and other benefit liabilities | B43: -624 | C43: -532 | D43: -422 | E43: -561
A44: Currency translation adjustment and cash flow hedges | B44: -57 | C44: -44 | D44: -469 | E44: -38
A45: Total shareholders' investment | B45: =SUM(B39:B44) -> 15821 | C45: =SUM(C39:C44) -> 16558 | D45: =SUM(D39:D44) -> 16231 | E45: =SUM(E39:E44) -> 13997
...

Sheet CF
A1: Ticker | B1: TGT
A2: Company | B2: Target
A4: (millions) | B4: 2011 | C4: 2012 | D4: 2013 | E4: 2014
A6: Operating activities
A7: Net earnings | B7: =IS!B23 -> 2929 | C7: =IS!C23 -> 2999 | D7: =IS!D23 -> 1971 | E7: =IS!E23 -> -1636
A8: Losses from Discontinued Operations | B8: =IS!B22 -> 0 | C8: =IS!C22 -> -316 | D8: =IS!D22 -> -723 | E8: =IS!E22 -> -4085
A9: Net Earnings from Continued Operations | B9: =B7-B8 -> 2929 | C9: =C7-C8 -> 3315 | D9: =D7-D8 -> 2694 | E9: =E7-E8 -> 2449
A10: Depreciation and amortization | B10: =IS!B14 -> 2131 | C10: =IS!C14 -> 2044 | D10: =IS!D14 -> 1996 | E10: =IS!E14 -> 2129
A11: Share-based compensation expense | B11: 90 | C11: 102 | D11: 106 | E11: 71
A12: Deferred income taxes | B12: 371 | C12: 67 | D12: 58 | E12: 7
A13: Bad debt expense (a) | B13: 154 | C13: 0 | D13: 445 | E13: 285
A14: Gain on receivables held for sale | B14: 0 | C14: -161 | D14: -391 | E14: 0
A15: Noncash (gains)/losses and other, net | B15: 22 | C15: 220 | D15: 121 | E15: 40
A16: Changes in operating accounts:
A17: Accounts receivable originated at Target | B17: -187 | C17: -217 | D17: 2860 | E17: 0
A18: Inventory | B18: -322 | C18: 160 | D18: -504 | E18: -512
A19: Other current assets | B19: -150 | C19: -155 | D19: -79 | E19: -115
A20: Other noncurrent assets | B20: 43 | C20: 0 | D20: 0 | E20: 0
A21: Accounts payable | B21: 232 | C21: 193 | D21: 213 | E21: 777
A22: Accrued and other current liabilities | B22: 218 | C22: 0 | D22: 0 | E22: 0
A23: Other noncurrent liabilities | B23: -97 | C23: 0 | D23: 0 | E23: 0
A24: Cash flow provided by operations - Continuing Operations | B24: =SUM(B9:B23) -> 5434 | C24: =SUM(C9:C23) -> 5568 | D24: =SUM(D9:D23) -> 7519 | E24: =SUM(E9:E23) -> 5131
A25: Cash flow provided by operations - Discontinued Operations | B25: 0 | C25: -243 | D25: -999 | E25: -692
A26: Cash provided by Operations | B26: =B24+B25 -> 5434 | C26: =C24+C25 -> 5325 | D26: =D24+D25 -> 6520 | E26: =E24+E25 -> 4439
A28: Investing activities
A29: Expenditures for property and equipment | B29: -4368 | C29: -3277 | D29: -3453 | E29: -1786
A30: Proceeds from disposal of property and equipment | B30: 37 | C30: 66 | D30: 86 | E30: 95
A31: Change in accounts receivable originated at third parties | B31: 259 | C31: 254 | D31: 0 | E31: 0
A32: Other investments | B32: -108 | C32: 102 | D32: 3096 | E32: 86
A33: Cash flow required for investing activities | B33: =SUM(B29:B32) -> -4180 | C33: =SUM(C29:C32) -> -2855 | D33: =SUM(D29:D32) -> -271 | E33: =SUM(E29:E32) -> -1605
A35: Financing activities
A36: Change in commercial paper, net | B36: 0 | C36: 970 | D36: -890 | E36: -80
A37: Additions to short-term debt | B37: 1500 | C37: 0 | D37: 0 | E37: 0
A38: Reductions of short-term debt | B38: 0 | C38: -1500 | D38: 0 | E38: 0
A39: Additions to long-term debt | B39: 1994 | C39: 1971 | D39: 0 | E39: 1993
A40: Reductions of long-term debt | B40: -3125 | C40: -1529 | D40: -3463 | E40: -2079
A41: Dividends paid | B41: -750 | C41: -869 | D41: -1006 | E41: -1205
A42: Repurchase of stock | B42: -1842 | C42: -1875 | D42: -1461 | E42: 0
A43: Stock option exercises and related tax benefit | B43: 89 | C43: 360 | D43: 456 | E43: 373
A44: Other | B44: -6 | C44: -16 | D44: 0 | E44: 0
...

Sheet Ratios
A1: Ticker | B1: TGT
A2: Company | B2: Target
B4: 2011 | C4: 2012 | D4: 2013 | E4: 2014
A5: Profitability Ratios
A6: Gross Profit Margin
A7: EBITDA Margin
A8: EBIT Margin
A9: Net Income Margin
A11: Activity Ratios
A12: Inventory Turnover
A13: Days of Inventory on Hand
A14: Receivables Turnover
A15: Days of Sales Outstanding
A16: Payables Turnover
A17: Number of Days of Payables
... A49: Cost of Sales Margin

Sheet Assumptions
A1: Ticker | B1: TGT
A2: Company | B2: Target
A4: Set of Cases: | B4: Best
B5: Base
B6: Worst
F7: Input Assumptions
A8: Case: | F8: Case: | G8: Best | J8: Case: | K8: Base | N8: Case: | O8: Worst
B9: 2015P | C9: 2016P | D9: 2017P | F9: 2015P | G9: 2016P | H9: 2017P | J9: 2015P | K9: 2016P | L9: 2017P | N9: 2015P | O9: 2016P | P9: 2017P
A10: Sales Growth | F10: 0.05 | G10: 0.05 | H10: 0.05 | J10: 0.02 | K10: 0.02 | L10: 0.02 | N10: -0.01 | O10: 0 | P10: 0.01
A11: Cost of Sales Margin | F11: 0.69 | G11: 0.69 | H11: 0.69 | J11: 0.7 | K11: 0.7 | L11: 0.7 | N11: 0.71 | O11: 0.71 | P11: 0.71
A12: Total Asset Growth | F12: 0.03 | G12: 0.03 | H12: 0.03 | J12: 0.01 | K12: 0.01 | L12: 0.01 | N12: -0.05 | O12: -0.05 | P12: -0.05
A13: Tax Rate | F13: 0.34 | G13: 0.34 | H13: 0.34 | J13: 0.35 | K13: 0.35 | L13: 0.35 | N13: 0.3 | O13: 0.3 | P13: 0.3
A14: SG&A as a % of Sales | F14: 0.2 | G14: 0.2 | H14: 0.2 | J14: 0.22 | K14: 0.22 | L14: 0.22 | N14: 0.23 | O14: 0.23 | P14: 0.23
A15: AR as % of sales | F15: 0 | G15: 0 | H15: 0 | J15: 0 | K15: 0 | L15: 0 | N15: 0 | O15: 0 | P15: 0
A16: Inventory as % of COGS | F16: 0.16 | G16: 0.16 | H16: 0.16 | J16: 0.17 | K16: 0.17 | L16: 0.17 | N16: 0.18 | O16: 0.18 | P16: 0.18
A17: AP as % of COGS | F17: 0.14 | G17: 0.14 | H17: 0.14 | J17: 0.15 | K17: 0.15 | L17: 0.15 | N17: 0.16 | O17: 0.16 | P17: 0.16
A18: Debt to Assets | F18: 0.275 | G18: 0.275 | H18: 0.275 | J18: 0.3 | K18: 0.3 | L18: 0.3 | N18: 0.325 | O18: 0.325 | P18: 0.325
A19: Capital expenditures as % of revenue | F19: 0.045 | G19: 0.045 | H19: 0.045 | J19: 0.05 | K19: 0.05 | L19: 0.05 | N19: 0.055 | O19: 0.055 | P19: 0.055
A20: Depreciation as % of Net PPE | F20: 0.07 | G20: 0.07 | H20: 0.07 | J20: 0.07 | K20: 0.07 | L20: 0.07 | N20: 0.07 | O20: 0.07 | P20: 0.07
A21: Interest Rate on Debt | F21: 0.05 | G21: 0.05 | H21: 0.05 | J21: 0.07 | K21: 0.07 | L21: 0.07 | N21: 0.08 | O21: 0.08 | P21: 0.08
A22: Dividend Payout Ratio | F22: 0.55 | G22: 0.55 | H22: 0.55 | J22: 0.4 | K22: 0.4 | L22: 0.4 | N22: 0.4 | O22: 0.4 | P22: 0.4

Sheet Projections
A1: Ticker | B1: TGT
A2: Company | B2: Target
A3: Case | B3: =Assumptions!B8 -> 0
A5: (millions, except per share data) | B5: 2015P | C5: 2016P | D5: 2017P
A7: Total revenues
A8: Cost of sales
A9: Gross Profit
A10: Selling, general and administrative expenses
A11: Credit card expenses | B11: 0 | C11: 0 | D11: 0
A12: EBITDA
A13: Depreciation and amortization
A14: Gain on receivables held for sale | B14: 0 | C14: 0 | D14: 0
A15: EBIT
A16: Interest expense
A17: EBT
A18: Provision for income taxes
A19: Net earnings
A20: Basic earnings per share
A22: Weighted average common shares outstanding
A24: Supplemental
A25: Net PPE
A26: CAPEX
A27: Total Assets
A28: Total Debt
... A30: Forecasted Shares Outstanding

Sheet Valuation
A1: Ticker | B1: TGT
A2: Company | B2: Target
A3: Case | B3: =Assumptions!B8 -> 0
A5: Current P/E | B5: 16.97
A6: Current Price | B6: 76.61
B8: 2015P | C8: 2016P | D8: 2017P
A9: EPS
A10: P/E Worst | B10: 12.5 | C10: 12.5 | D10: 12.5
A11: P/E Base | B11: 20 | C11: 20 | D11: 20
A12: P/E Best | B12: 30 | C12: 30 | D12: 30
A14: Forecasted Price
A15: Worst Case
A16: Base Case
A17: Best Case

Sheet DDM-Val
A1: Ticker | B1: TGT
A2: Company | B2: Target
A3: Case | B3: =Assumptions!B8 -> 0
A5: Discount Rate | B5: 0.05
A6: Terminal Growth Rate | B6: 0.03
A7: Terminal Value
B9: 2015P | C9: 2016P | D9: 2017P
A10: Dividend Per Share
A11: Growth Rate
A12: Time Period | B12: 1 | C12: 2 | D12: 3
A14: DDM Valuation
B16: =B9 -> 2015P | C16: =C9 -> 2016P | D16: =D9 -> 2017P | E16: Terminal Value | F16: Total
A17: Discounted Value

Sheet WACC
A1: Ticker | B1: TGT
A2: Company | B2: Target
A3: Case | B3: =Assumptions!B8 -> 0
A5: Tax Rate | D5: EV
A6: Market Value ($M) | D6: Equity %
A7: Debt Value ($M) | D7: Debt %
A8: Cost of Debt | D8: 1-T
A10: TGT Beta | B10: 0.8
A11: Exp Market Return | B11: 0.08
A12: Risk Free Rate | B12: 0
A14: CAPM Cost of Equity
E15: Equity | F15: Debt | G15: WACC
A16: WACC

Sheet DCF-Val
A1: Ticker | B1: TGT
A2: Company | B2: Target
A3: Case | B3: =Assumptions!B8 -> 0
B5: 2015P | C5: 2016P | D5: 2017P | F5: Inputs and Assumptions
A6: CFO | F6: Discount Rate
A7: CAPEX | F7: Growth Rate | G7: 0.02
A8: Free Cash Flow
A9: Free Cash Flow Per Share | F9: Terminal Value
A10: Time Period | B10: 1 | C10: 2 | D10: 3
F11: Free Cash Flow Value
A12: Cash Flow Statement Schedule
A13: Net Income
A14: Depreciation
A15: Share Based Comp | B15: 100 | C15: 100 | D15: 100
A16: Changes in operating accounts:
A17: Accounts receivable originated at Target
A18: Inventory
A19: Accounts payable
A20: CFO
A22: Accounts Receivable
A23: Inventory
A24: Accounts Payable
A25: Shares Outstanding
